You have passed `None` for safety_checker to disable its functionality in <class 'diffusers.pipelines.stable_diffusion.pipeline_stable_diffusion.StableDiffusionPipeline'>. Note that this might lead to problems when using <class 'diffusers.pipelines.stable_diffusion.pipeline_stable_diffusion.StableDiffusionPipeline'> and is not recommended.
You have disabled the safety checker for <class 'diffusers.pipelines.stable_diffusion.pipeline_stable_diffusion.StableDiffusionPipeline'> by passing `safety_checker=None`. Ensure that you abide to the conditions of the Stable Diffusion license and do not expose unfiltered results in services or applications open to the public. Both the diffusers team and Hugging Face strongly recommend to keep the safety filter enabled in all public facing circumstances, disabling it only for use-cases that involve analyzing network behavior or auditing its results. For more information, please have a look at https://github.com/huggingface/diffusers/pull/254 .
Load stable_diffusion_model:v14 from wandb cloud checkpoint
Output will be saved in ../book dataset/v14 inference
model running on device cuda:0
Generating images on the test set to compute FID score......
Traceback (most recent call last):
  File "/usr/lib/python3.8/runpy.py", line 194, in _run_module_as_main
    return _run_code(code, main_globals, None,
  File "/usr/lib/python3.8/runpy.py", line 87, in _run_code
    exec(code, run_globals)
  File "/home/wenxuan/Stable-diffusion-for-book-cover-generation/sd-inference.py", line 430, in <module>
    get_fid_images(pipeline, save_dir)
  File "/home/wenxuan/Stable-diffusion-for-book-cover-generation/sd-inference.py", line 186, in get_fid_images
    df = pd.read_csv(args.data_root+"/df_test.csv").iloc[num_generated:]
  File "/home/wenxuan/sd_training/lib/python3.8/site-packages/pandas/core/indexing.py", line 1073, in __getitem__
    return self._getitem_axis(maybe_callable, axis=axis)
  File "/home/wenxuan/sd_training/lib/python3.8/site-packages/pandas/core/indexing.py", line 1602, in _getitem_axis
    return self._get_slice_axis(key, axis=axis)
  File "/home/wenxuan/sd_training/lib/python3.8/site-packages/pandas/core/indexing.py", line 1637, in _get_slice_axis
    labels._validate_positional_slice(slice_obj)
  File "/home/wenxuan/sd_training/lib/python3.8/site-packages/pandas/core/indexes/base.py", line 4212, in _validate_positional_slice
    self._validate_indexer("positional", key.start, "iloc")
  File "/home/wenxuan/sd_training/lib/python3.8/site-packages/pandas/core/indexes/base.py", line 6634, in _validate_indexer
    raise self._invalid_indexer(form, key)
TypeError: cannot do positional indexing on RangeIndex with these indexers [[]] of type list